File: 2024_09_17_sucrose_chm343_dsc-4.txt
Filename	2024_09_17_sucrose_chm343_dsc
Instrument name	DSC2A-00468 (192.168.1.100)
Operator	CHM343
rundate	9/17/2024
Sample name	2024_09_17_Sucrose_CHM343_DSC
Sample notes	Sucrose in Al Hermetic Sealed Pan, with ref Al pan.
proceduresegments	Equilibrate 30.00 °C; Ramp 10.00 °C/min to 210.00 °C; Isothermal 1.0 min; Ramp 10.00 °C/min to 30.00 °C; Isothermal 1.0 min; Ramp 10.00 °C/min to 210.00 °C
[File Parameters]
Run date	9/17/2024 4:04:31 PM
Trios version	5.1.1.46572
Original File Name	C:\ProgramData\TA Instruments\TRIOS\Data\2024_09_17_Sucrose_CHM343_DSC.tri
Current File Name	c:\users\larry\downloads\2024_09_17_sucrose_chm343_dsc.tri
[Procedure]
Procedure Name	CHM343_Fall2024_Sucrose
Sample Name	2024_09_17_Sucrose_CHM343_DSC
Sample Mass	3.13 mg
Reference Sample Mass	0 mg
Pan Mass	53.68 mg
Pan Number	23
Reference Pan Mass	54 mg
Reference Pan Number	19
Pan Type	Aluminum
Comments	Sucrose in Al Hermetic Sealed Pan, with ref Al pan.
Project Name	Lab 4 - Fall 2024
Operator	CHM343
Test	Custom
Unload Max Temperature	30
Unload Min Temperature	30
Load Max Temperature	30
Load Min Temperature	30
Stop on Gas Flow Error	Yes
[Signal List]
Signal #1	Time (min)
Signal #2	Temperature (°C)
Signal #3	Heat Flow (mW)
Signal #4	Delta T (µV)
Signal #5	Delta Tzero (µV)
Signal #6	Tzero Temperature (°C)
Signal #7	Cell Purge (mL/min)
Signal #8	Heater Temp (°C)
Signal #9	Power Delivered (W)
Signal #10	Reference Junction Temperature (°C)
Signal #11	Flange Temperature (°C)
Signal #12	Heat Flow Phase (rad)
Signal #13	Total Heat Capacity (J/°C)
Signal #14	Heat Capacity (J/°C)
[Configuration]
Company Name	ASU
Instrument Name	DSC2A-00468
Instrument Type	DSC2500
Serial Number	DSC2A-00468
IP	192.168.1.100
Location of Instrument	MRRC
DisplayType	Unknown
Sample Interval 	0.1 s/pt
Selected Heat Flow	T4P
Exotherm Direction	Down
Cell Serial	DRC2-00792
Lid Type	Standard
Cooler	RCS 90
Leave Cooler on at End of Sequence	On
Gas 2	Nitrogen
Gas Selected	Channel 1
Flow Rate	50 mL/min
Secondary Purge	On
Licensed Heat Flow	Heat Flow T4P
Modulation Licensed	Yes
[Versions]
Common IDD Version	1
Cortex Version	VER 2.10.2.31
Driver	5.0.0.6
GDM Version	1.0.3.3
TouchscreenVersion	1.0.0.16145
FEP Version	1.2.1.21
FEP Bootloader	2.0.0.5
AutoSampler Version	2.1.1.26
Auto Sampler Bootloader	2.0.0.5
FCM Version	1.1.0.3
FCM Bootloader	2.0.0.5
[Experiment Logs]
Experiment Log Entry # 1	Equilibrate Segment 30 (C) Started
Experiment Log Entry # 3	Air Cool is off.
Experiment Log Entry # 5	Ramp Segment 10 C/min to 210 Started
Experiment Log Entry # 7	Isothermal Segment 1 min started
Experiment Log Entry # 9	Ramp Segment 10 C/min to 30 Started
Experiment Log Entry # 11	Isothermal Segment 1 min started
Experiment Log Entry # 13	Ramp Segment 10 C/min to 210 Started
[Method Log]
Method Log Entry # 1	Equilibrate 30 °C
Method Log Entry # 2	(Ramp 22137) Ramp 10 °C/minute to 210 °C
Method Log Entry # 3	Isothermal 1 minutes
Method Log Entry # 4	(Ramp 22139) Ramp 10 °C/minute to 30 °C
Method Log Entry # 5	Isothermal 1 minutes
Method Log Entry # 6	(Ramp 22141) Ramp 10 °C/minute to 210 °C
Cell Serial	DRC2-00792
[T1 Calibration]
Slope	-0.008529666
Offset	9.636258
Initial Temperature	98.23
GUID	f8bfdadc-4977-4fdf-ba6d-0ba9134940c3
[TZero Calibration]
Date Applied	11/29/2022 3:06:13 PM
Description	From -89.059 °C to 396.009 °C at 20.000°C/min
Gas Type	Nitrogen
Pan Type	None
Source Files 1	C:\Users\yargerlab\Desktop\DSC Data\General\TZero_calibration_11_29_22_2nd(2).tri
Source Files 2	C:\Users\yargerlab\Desktop\DSC Data\General\TZero_calibration_11_29_22_2nd(3).tri
Delta T Offset	13.05235
Delta T Slope	-0.007271007
Delta T0 Offset	-13.69128
Delta T0 Slope	0.06063341
[Temperature Calibration]
Date Applied	11/29/2022 6:12:28 PM
Description	From 106.590 °C to 186.590 °C at 10.000°C/min
Gas Type	Nitrogen
Pan Type	Tzero Aluminum Hermetic
Source Files 1	C:\Users\yargerlab\Desktop\DSC Data\General\Indium(6).tri
Measured 1	157.391
Known 1	156.598
[Cell Constant Calibration]
Date Applied	11/29/2022 6:12:29 PM
Description	From 106.590 °C to 186.590 °C at 10.000°C/min
Gas Type	Nitrogen
Pan Type	Tzero Aluminum Hermetic
Source Files 1	C:\Users\yargerlab\Desktop\DSC Data\General\Indium(6).tri
T4P KCell	1.006051
Onset Slope	63.26126 mW/°C
[Direct Cp Calibration]
Date Applied	11/30/2022 10:04:51 AM
Description	From -79.983 °C to 298.409 °C at 10.000°C/min
Gas Type	Nitrogen
Pan Type	Tzero Aluminum Hermetic
Source Files 1	C:\Users\yargerlab\Desktop\DSC Data\General\Sapphire_Heat_Capacity_11_30_22.tri
[Rev Cp Calibration]
Date Applied	11/30/2022 12:58:51 PM
Description	From -79.996 °C to 292.812 °C at 3.000°C/min
Gas Type	Nitrogen
Pan Type	Tzero Aluminum Hermetic
Source Files 1	C:\Users\yargerlab\Desktop\DSC Data\General\Sapphire_MDSC_Calibration_11_30_22.tri
[step]
Ramp 10.00 °C/min to 210.00 °C
Time	Temperature	Heat Flow (Normalized)
min	°C	W/g
0.00	30.06	-0.053
0.01	30.06	-0.052
0.03	30.06	-0.050
0.04	30.07	-0.049
0.05	30.08	-0.049
0.07	30.10	-0.049
0.08	30.12	-0.057
0.09	30.16	-0.070
0.11	30.21	-0.077
0.12	30.28	-0.077
0.13	30.35	-0.074
0.15	30.44	-0.052
0.16	30.53	-0.022
0.17	30.62	0.002
0.19	30.72	0.027
0.20	30.83	0.048
0.21	30.94	0.067
0.23	31.05	0.082
0.24	31.16	0.096
0.25	31.28	0.109
0.27	31.40	0.117
0.28	31.51	0.127
0.29	31.63	0.135
0.31	31.76	0.143
0.32	31.88	0.149
0.33	32.01	0.158
0.35	32.13	0.162
0.36	32.26	0.168
0.37	32.39	0.170
0.39	32.51	0.175
0.40	32.64	0.179
0.41	32.77	0.181
0.43	32.90	0.182
0.44	33.03	0.185
0.45	33.16	0.187
0.47	33.29	0.189
0.48	33.42	0.192
0.49	33.55	0.192
0.51	33.68	0.193
0.52	33.81	0.194
0.53	33.94	0.194
0.55	34.07	0.195
0.56	34.20	0.195
0.57	34.34	0.196
0.59	34.47	0.197
0.60	34.60	0.197
0.61	34.73	0.198
0.63	34.86	0.198
0.64	34.99	0.199
0.65	35.13	0.199
0.67	35.26	0.199
0.68	35.39	0.200
0.69	35.52	0.200
0.71	35.65	0.200
0.72	35.79	0.201
0.73	35.92	0.201
0.75	36.05	0.202
0.76	36.18	0.202
0.77	36.32	0.202
0.79	36.45	0.202
0.80	36.58	0.203
0.81	36.71	0.203
0.83	36.85	0.203
0.84	36.98	0.204
0.85	37.11	0.204
0.87	37.24	0.204
0.88	37.37	0.204
0.89	37.51	0.204
0.91	37.64	0.205
0.92	37.77	0.205
0.93	37.91	0.205
0.95	38.04	0.205
0.96	38.17	0.206
0.97	38.30	0.206
0.99	38.44	0.206
1.00	38.57	0.206
1.01	38.70	0.206
1.03	38.83	0.206
1.04	38.97	0.207
1.05	39.10	0.207
1.07	39.23	0.207
1.08	39.37	0.207
1.09	39.50	0.207
1.11	39.63	0.207
1.12	39.77	0.207
1.13	39.90	0.208
1.15	40.03	0.208
1.16	40.16	0.208
1.17	40.30	0.208
1.19	40.43	0.208
1.20	40.56	0.208
1.21	40.70	0.208
1.23	40.83	0.208
1.24	40.96	0.208
1.25	41.10	0.208
1.27	41.23	0.208
1.28	41.36	0.209
1.29	41.50	0.209
1.31	41.63	0.209
1.32	41.76	0.209
1.33	41.89	0.209
1.35	42.03	0.209
1.36	42.16	0.209
1.37	42.29	0.209
1.39	42.43	0.209
1.40	42.56	0.209
1.41	42.69	0.209
1.43	42.83	0.209
1.44	42.96	0.210
1.45	43.09	0.210
1.47	43.23	0.210
1.48	43.36	0.210
1.49	43.49	0.210
1.51	43.63	0.210
1.52	43.76	0.210
1.53	43.89	0.210
1.55	44.03	0.210
1.56	44.16	0.210
1.57	44.29	0.210
1.59	44.42	0.210
1.60	44.56	0.210
1.61	44.69	0.210
1.63	44.82	0.210
1.64	44.96	0.210
1.65	45.09	0.211
1.67	45.22	0.211
1.68	45.36	0.211
1.69	45.49	0.211
1.71	45.62	0.211
1.72	45.76	0.211
1.73	45.89	0.211
1.75	46.03	0.211
1.76	46.16	0.211
1.77	46.29	0.211
1.79	46.42	0.211
1.80	46.56	0.211
1.81	46.69	0.211
1.83	46.82	0.211
1.84	46.96	0.211
1.85	47.09	0.211
1.87	47.22	0.211
1.88	47.36	0.211
1.89	47.49	0.211
1.91	47.62	0.212
1.92	47.76	0.212
1.93	47.89	0.212
1.95	48.02	0.212
1.96	48.16	0.212
1.97	48.29	0.212
1.99	48.42	0.212
2.00	48.56	0.212
2.01	48.69	0.212
2.03	48.83	0.212
2.04	48.96	0.212
2.05	49.09	0.212
2.07	49.23	0.212
2.08	49.36	0.212
2.09	49.49	0.212
2.11	49.63	0.212
2.12	49.76	0.212
2.13	49.89	0.212
2.15	50.03	0.213
2.16	50.16	0.213
2.17	50.29	0.213
2.19	50.43	0.213
2.20	50.56	0.213
2.21	50.69	0.213
2.23	50.83	0.213
2.24	50.96	0.213
2.25	51.09	0.213
2.27	51.23	0.213
2.28	51.36	0.213
2.29	51.49	0.213
2.31	51.63	0.213
2.32	51.76	0.213
2.33	51.89	0.213
2.35	52.03	0.213
2.36	52.16	0.214
2.37	52.29	0.214
2.39	52.43	0.214
2.40	52.56	0.214
2.41	52.69	0.214
2.43	52.83	0.214
2.44	52.96	0.214
2.45	53.10	0.214
2.47	53.23	0.214
2.48	53.36	0.214
2.49	53.49	0.214
2.51	53.63	0.214
2.52	53.76	0.214
2.53	53.90	0.214
2.55	54.03	0.214
2.56	54.16	0.214
2.57	54.30	0.214
2.59	54.43	0.215
2.60	54.56	0.215
2.61	54.69	0.215
2.63	54.83	0.215
2.64	54.96	0.215
2.65	55.10	0.215
2.67	55.23	0.215
2.68	55.36	0.215
2.69	55.50	0.215
2.71	55.63	0.215
2.72	55.76	0.215
2.73	55.90	0.215
2.75	56.03	0.215
2.76	56.16	0.215
2.77	56.30	0.215
2.79	56.43	0.215
2.80	56.56	0.215
2.81	56.70	0.215
2.83	56.83	0.216
2.84	56.96	0.216
2.85	57.10	0.216
2.87	57.23	0.216
2.88	57.36	0.216
2.89	57.50	0.216
2.91	57.63	0.216
2.92	57.76	0.216
2.93	57.90	0.216
2.95	58.03	0.216
2.96	58.16	0.216
2.97	58.30	0.216
2.99	58.43	0.216
3.00	58.56	0.216
3.01	58.70	0.217
3.03	58.83	0.217
3.04	58.96	0.217
3.05	59.10	0.217
3.07	59.23	0.217
3.08	59.37	0.217
3.09	59.50	0.217
3.11	59.63	0.217
3.12	59.77	0.217
3.13	59.90	0.217
3.15	60.03	0.217
3.16	60.17	0.218
3.17	60.30	0.217
3.19	60.43	0.218
3.20	60.57	0.218
3.21	60.70	0.218
3.23	60.83	0.218
3.24	60.97	0.218
3.25	61.10	0.218
3.27	61.23	0.218
3.28	61.37	0.218
3.29	61.50	0.218
3.31	61.63	0.218
3.32	61.77	0.218
3.33	61.90	0.218
3.35	62.03	0.218
3.36	62.17	0.218
3.37	62.30	0.218
3.39	62.43	0.218
3.40	62.57	0.219
3.41	62.70	0.219
3.43	62.83	0.219
3.44	62.97	0.219
3.45	63.10	0.219
3.47	63.23	0.219
3.48	63.37	0.219
3.49	63.50	0.219
3.51	63.63	0.219
3.52	63.77	0.219
3.53	63.90	0.219
3.55	64.03	0.220
3.56	64.17	0.220
3.57	64.30	0.220
3.59	64.44	0.220
3.60	64.57	0.220
3.61	64.70	0.220
3.63	64.84	0.220
3.64	64.97	0.220
3.65	65.10	0.220
3.67	65.24	0.220
3.68	65.37	0.220
3.69	65.50	0.221
3.71	65.64	0.221
3.72	65.77	0.221
3.73	65.90	0.221
3.75	66.04	0.221
3.76	66.17	0.221
3.77	66.30	0.221
3.79	66.44	0.221
3.80	66.57	0.221
3.81	66.70	0.221
3.83	66.84	0.221
3.84	66.97	0.221
3.85	67.10	0.221
3.87	67.24	0.221
3.88	67.37	0.222
3.89	67.51	0.222
3.91	67.64	0.222
3.92	67.77	0.222
3.93	67.91	0.222
3.95	68.04	0.222
3.96	68.17	0.222
3.97	68.31	0.222
3.99	68.44	0.222
4.00	68.57	0.222
4.01	68.71	0.222
4.03	68.84	0.223
4.04	68.97	0.223
4.05	69.11	0.223
4.07	69.24	0.223
4.08	69.37	0.223
4.09	69.51	0.223
4.11	69.64	0.223
4.12	69.77	0.223
4.13	69.91	0.223
4.15	70.04	0.223
4.16	70.17	0.223
4.17	70.31	0.224
4.19	70.44	0.224
4.20	70.57	0.224
4.21	70.71	0.224
4.23	70.84	0.224
4.24	70.97	0.224
4.25	71.11	0.224
4.27	71.24	0.224
4.28	71.38	0.224
4.29	71.51	0.225
4.31	71.64	0.225
4.32	71.77	0.225
4.33	71.91	0.225
4.35	72.04	0.225
4.36	72.18	0.225
4.37	72.31	0.225
4.39	72.44	0.225
4.40	72.58	0.225
4.41	72.71	0.225
4.43	72.84	0.225
4.44	72.97	0.225
4.45	73.11	0.226
4.47	73.24	0.226
4.48	73.38	0.226
4.49	73.51	0.226
4.51	73.64	0.226
4.52	73.78	0.226
4.53	73.91	0.226
4.55	74.04	0.226
4.56	74.18	0.226
4.57	74.31	0.226
4.59	74.44	0.226
4.60	74.58	0.226
4.61	74.71	0.227
4.63	74.84	0.227
4.64	74.98	0.227
4.65	75.11	0.227
4.67	75.25	0.227
4.68	75.38	0.227
4.69	75.51	0.227
4.71	75.64	0.227
4.72	75.78	0.227
4.73	75.91	0.227
4.75	76.05	0.228
4.76	76.18	0.228
4.77	76.31	0.228
4.79	76.45	0.228
4.80	76.58	0.228
4.81	76.71	0.228
4.83	76.84	0.228
4.84	76.98	0.228
4.85	77.11	0.228
4.87	77.25	0.229
4.88	77.38	0.229
4.89	77.51	0.229
4.91	77.65	0.229
4.92	77.78	0.229
4.93	77.91	0.229
4.95	78.05	0.229
4.96	78.18	0.229
4.97	78.31	0.229
4.99	78.45	0.229
5.00	78.58	0.230
5.01	78.71	0.230
5.03	78.85	0.230
5.04	78.98	0.230
5.05	79.11	0.230
5.07	79.25	0.230
5.08	79.38	0.230
5.09	79.51	0.230
5.11	79.65	0.230
5.12	79.78	0.230
5.13	79.91	0.230
5.15	80.05	0.231
5.16	80.18	0.231
5.17	80.31	0.231
5.19	80.45	0.231
5.20	80.58	0.231
5.21	80.71	0.231
5.23	80.85	0.231
5.24	80.98	0.231
5.25	81.11	0.231
5.27	81.25	0.231
5.28	81.38	0.231
5.29	81.51	0.232
5.31	81.65	0.232
5.32	81.78	0.232
5.33	81.91	0.232
5.35	82.05	0.232
5.36	82.18	0.232
5.37	82.31	0.232
5.39	82.45	0.232
5.40	82.58	0.232
5.41	82.72	0.232
5.43	82.85	0.232
5.44	82.98	0.232
5.45	83.12	0.232
5.47	83.25	0.233
5.48	83.38	0.233
5.49	83.52	0.233
5.51	83.65	0.233
5.52	83.78	0.233
5.53	83.92	0.233
5.55	84.05	0.233
5.56	84.18	0.233
5.57	84.32	0.233
5.59	84.45	0.233
5.60	84.58	0.233
5.61	84.72	0.233
5.63	84.85	0.233
5.64	84.98	0.233
5.65	85.12	0.234
5.67	85.25	0.234
5.68	85.38	0.234
5.69	85.52	0.234
5.71	85.65	0.234
5.72	85.78	0.234
5.73	85.92	0.234
5.75	86.05	0.234
5.76	86.18	0.234
5.77	86.32	0.234
5.79	86.45	0.234
5.80	86.58	0.234
5.81	86.72	0.235
5.83	86.85	0.235
5.84	86.99	0.235
5.85	87.12	0.235
5.87	87.25	0.235
5.88	87.39	0.235
5.89	87.52	0.235
5.91	87.65	0.235
5.92	87.79	0.235
5.93	87.92	0.235
5.95	88.05	0.235
5.96	88.19	0.235
5.97	88.32	0.236
5.99	88.45	0.236
6.00	88.59	0.236
6.01	88.72	0.236
6.03	88.85	0.236
6.04	88.99	0.236
6.05	89.12	0.236
6.07	89.25	0.236
6.08	89.39	0.236
6.09	89.52	0.237
6.11	89.65	0.237
6.12	89.79	0.237
6.13	89.92	0.237
6.15	90.05	0.237
6.16	90.19	0.237
6.17	90.32	0.237
6.19	90.45	0.237
6.20	90.59	0.238
6.21	90.72	0.238
6.23	90.85	0.238
6.24	90.99	0.238
6.25	91.12	0.238
6.27	91.25	0.238
6.28	91.39	0.238
6.29	91.52	0.239
6.31	91.65	0.239
6.32	91.79	0.239
6.33	91.92	0.239
6.35	92.06	0.239
6.36	92.19	0.239
6.37	92.32	0.239
6.39	92.46	0.239
6.40	92.59	0.240
6.41	92.72	0.240
6.43	92.86	0.240
6.44	92.99	0.240
6.45	93.12	0.240
6.47	93.26	0.240
6.48	93.39	0.240
6.49	93.52	0.240
6.51	93.66	0.241
6.52	93.79	0.241
6.53	93.92	0.241
6.55	94.06	0.241
6.56	94.19	0.241
6.57	94.32	0.241
6.59	94.46	0.241
6.60	94.59	0.241
6.61	94.72	0.242
6.63	94.86	0.242
6.64	94.99	0.242
6.65	95.12	0.242
6.67	95.26	0.242
6.68	95.39	0.242
6.69	95.52	0.242
6.71	95.66	0.242
6.72	95.79	0.243
6.73	95.92	0.243
6.75	96.06	0.243
6.76	96.19	0.243
6.77	96.32	0.243
6.79	96.46	0.243
6.80	96.59	0.243
6.81	96.73	0.243
6.83	96.86	0.244
6.84	96.99	0.244
6.85	97.13	0.244
6.87	97.26	0.244
6.88	97.39	0.244
6.89	97.53	0.244
6.91	97.66	0.244
6.92	97.79	0.245
6.93	97.92	0.245
6.95	98.06	0.245
6.96	98.19	0.245
6.97	98.33	0.245
6.99	98.46	0.245
7.00	98.59	0.245
7.01	98.73	0.245
7.03	98.86	0.245
7.04	98.99	0.246
7.05	99.13	0.246
7.07	99.26	0.246
7.08	99.39	0.246
7.09	99.53	0.246
7.11	99.66	0.246
7.12	99.79	0.246
7.13	99.93	0.247
7.15	100.06	0.247
7.16	100.19	0.247
7.17	100.33	0.247
7.19	100.46	0.247
7.20	100.59	0.247
7.21	100.73	0.247
7.23	100.86	0.248
7.24	100.99	0.248
7.25	101.13	0.248
7.27	101.26	0.248
7.28	101.39	0.248
7.29	101.53	0.248
7.31	101.66	0.248
7.32	101.79	0.249
7.33	101.93	0.249
7.35	102.06	0.249
7.36	102.19	0.249
7.37	102.33	0.249
7.39	102.46	0.249
7.40	102.59	0.249
7.41	102.73	0.249
7.43	102.86	0.250
7.44	103.00	0.250
7.45	103.13	0.250
7.47	103.26	0.250
7.48	103.40	0.250
7.49	103.53	0.250
7.51	103.66	0.250
7.52	103.80	0.250
7.53	103.93	0.251
7.55	104.06	0.251
7.56	104.20	0.251
7.57	104.33	0.251
7.59	104.46	0.251
7.60	104.59	0.251
7.61	104.73	0.251
7.63	104.86	0.251
7.64	104.99	0.252
7.65	105.13	0.252
7.67	105.26	0.252
7.68	105.40	0.252
7.69	105.53	0.252
7.71	105.66	0.252
7.72	105.80	0.252
7.73	105.93	0.253
7.75	106.06	0.253
7.76	106.20	0.253
7.77	106.33	0.253
7.79	106.46	0.253
7.80	106.60	0.253
7.81	106.73	0.253
7.83	106.86	0.253
7.84	107.00	0.253
7.85	107.13	0.254
7.87	107.26	0.254
7.88	107.40	0.254
7.89	107.53	0.254
7.91	107.66	0.254
7.92	107.80	0.254
7.93	107.93	0.254
7.95	108.06	0.255
7.96	108.20	0.255
7.97	108.33	0.255
7.99	108.46	0.255
8.00	108.60	0.255
8.01	108.73	0.255
8.03	108.86	0.255
8.04	109.00	0.256
8.05	109.13	0.256
8.07	109.26	0.256
8.08	109.40	0.256
8.09	109.53	0.256
8.11	109.66	0.256
8.12	109.80	0.257
8.13	109.93	0.257
8.15	110.06	0.257
8.16	110.20	0.257
8.17	110.33	0.257
8.19	110.46	0.257
8.20	110.60	0.257
8.21	110.73	0.258
8.23	110.86	0.258
8.24	111.00	0.258
8.25	111.13	0.258
8.27	111.26	0.258
8.28	111.40	0.258
8.29	111.53	0.258
8.31	111.67	0.258
8.32	111.80	0.259
8.33	111.93	0.259
8.35	112.07	0.259
8.36	112.20	0.259
8.37	112.33	0.259
8.39	112.47	0.259
8.40	112.60	0.259
8.41	112.73	0.260
8.43	112.87	0.260
8.44	113.00	0.260
8.45	113.13	0.260
8.47	113.27	0.260
8.48	113.40	0.260
8.49	113.53	0.260
8.51	113.67	0.261
8.52	113.80	0.261
8.53	113.93	0.261
8.55	114.07	0.261
8.56	114.20	0.261
8.57	114.33	0.261
8.59	114.47	0.261
8.60	114.60	0.262
8.61	114.73	0.262
8.63	114.87	0.262
8.64	115.00	0.262
8.65	115.13	0.262
8.67	115.27	0.262
8.68	115.40	0.262
8.69	115.53	0.262
8.71	115.67	0.263
8.72	115.80	0.263
8.73	115.93	0.263
8.75	116.07	0.263
8.76	116.20	0.263
8.77	116.34	0.263
8.79	116.47	0.263
8.80	116.60	0.264
8.81	116.73	0.264
8.83	116.87	0.264
8.84	117.00	0.264
8.85	117.14	0.264
8.87	117.27	0.264
8.88	117.40	0.264
8.89	117.54	0.265
8.91	117.67	0.265
8.92	117.80	0.265
8.93	117.94	0.265
8.95	118.07	0.265
8.96	118.20	0.265
8.97	118.34	0.266
8.99	118.47	0.266
9.00	118.60	0.266
9.01	118.74	0.266
9.03	118.87	0.266
9.04	119.00	0.266
9.05	119.14	0.266
9.07	119.27	0.267
9.08	119.40	0.267
9.09	119.54	0.267
9.11	119.67	0.267
9.12	119.80	0.267
9.13	119.94	0.267
9.15	120.07	0.268
9.16	120.20	0.268
9.17	120.34	0.268
9.19	120.47	0.268
9.20	120.60	0.268
9.21	120.74	0.268
9.23	120.87	0.268
9.24	121.00	0.269
9.25	121.14	0.269
9.27	121.27	0.269
9.28	121.40	0.269
9.29	121.54	0.269
9.31	121.67	0.269
9.32	121.80	0.269
9.33	121.94	0.270
9.35	122.07	0.270
9.36	122.20	0.270
9.37	122.34	0.270
9.39	122.47	0.270
9.40	122.61	0.270
9.41	122.74	0.270
9.43	122.87	0.271
9.44	123.01	0.271
9.45	123.14	0.271
9.47	123.27	0.271
9.48	123.40	0.272
9.49	123.54	0.272
9.51	123.67	0.272
9.52	123.81	0.272
9.53	123.94	0.272
9.55	124.07	0.272
9.56	124.20	0.272
9.57	124.34	0.272
9.59	124.47	0.273
9.60	124.60	0.273
9.61	124.74	0.273
9.63	124.87	0.273
9.64	125.01	0.273
9.65	125.14	0.273
9.67	125.27	0.273
9.68	125.41	0.274
9.69	125.54	0.274
9.71	125.67	0.274
9.72	125.81	0.274
9.73	125.94	0.274
9.75	126.07	0.275
9.76	126.21	0.275
9.77	126.34	0.275
9.79	126.47	0.275
9.80	126.61	0.275
9.81	126.74	0.275
9.83	126.87	0.276
9.84	127.01	0.276
9.85	127.14	0.276
9.87	127.27	0.276
9.88	127.41	0.276
9.89	127.54	0.277
9.91	127.67	0.277
9.92	127.81	0.277
9.93	127.94	0.277
9.95	128.07	0.277
9.96	128.21	0.277
9.97	128.34	0.278
9.99	128.47	0.278
10.00	128.61	0.278
10.01	128.74	0.278
10.03	128.87	0.278
10.04	129.01	0.278
10.05	129.14	0.278
10.07	129.27	0.279
10.08	129.41	0.279
10.09	129.54	0.279
10.11	129.67	0.279
10.12	129.81	0.279
10.13	129.94	0.279
10.15	130.07	0.280
10.16	130.21	0.280
10.17	130.34	0.280
10.19	130.47	0.280
10.20	130.61	0.280
10.21	130.74	0.281
10.23	130.87	0.281
10.24	131.01	0.281
10.25	131.14	0.281
10.27	131.27	0.281
10.28	131.41	0.282
10.29	131.54	0.282
10.31	131.67	0.282
10.32	131.81	0.282
10.33	131.94	0.282
10.35	132.08	0.282
10.36	132.21	0.282
10.37	132.34	0.283
10.39	132.47	0.283
10.40	132.61	0.283
10.41	132.74	0.283
10.43	132.88	0.283
10.44	133.01	0.283
10.45	133.14	0.284
10.47	133.28	0.284
10.48	133.41	0.284
10.49	133.54	0.284
10.51	133.68	0.284
10.52	133.81	0.284
10.53	133.94	0.284
10.55	134.08	0.285
10.56	134.21	0.285
10.57	134.34	0.285
10.59	134.48	0.285
10.60	134.61	0.285
10.61	134.74	0.285
10.63	134.88	0.286
10.64	135.01	0.286
10.65	135.14	0.286
10.67	135.28	0.286
10.68	135.41	0.286
10.69	135.54	0.286
10.71	135.68	0.287
10.72	135.81	0.287
10.73	135.94	0.287
10.75	136.08	0.287
10.76	136.21	0.287
10.77	136.34	0.287
10.79	136.48	0.288
10.80	136.61	0.288
10.81	136.74	0.288
10.83	136.88	0.288
10.84	137.01	0.288
10.85	137.14	0.288
10.87	137.28	0.288
10.88	137.41	0.288
10.89	137.54	0.289
10.91	137.68	0.289
10.92	137.81	0.289
10.93	137.94	0.289
10.95	138.08	0.289
10.96	138.21	0.289
10.97	138.34	0.289
10.99	138.48	0.290
11.00	138.61	0.290
11.01	138.75	0.290
11.03	138.88	0.290
11.04	139.01	0.290
11.05	139.14	0.290
11.07	139.28	0.291
11.08	139.41	0.291
11.09	139.55	0.291
11.11	139.68	0.291
11.12	139.81	0.291
11.13	139.94	0.291
11.15	140.08	0.292
11.16	140.21	0.292
11.17	140.34	0.292
11.19	140.48	0.292
11.20	140.61	0.292
11.21	140.74	0.292
11.23	140.88	0.292
11.24	141.01	0.293
11.25	141.14	0.293
11.27	141.28	0.293
11.28	141.41	0.293
11.29	141.54	0.293
11.31	141.68	0.293
11.32	141.81	0.293
11.33	141.95	0.294
11.35	142.08	0.294
11.36	142.21	0.294
11.37	142.35	0.294
11.39	142.48	0.294
11.40	142.61	0.294
11.41	142.75	0.295
11.43	142.88	0.295
11.44	143.01	0.295
11.45	143.15	0.295
11.47	143.28	0.295
11.48	143.41	0.296
11.49	143.55	0.296
11.51	143.68	0.296
11.52	143.81	0.296
11.53	143.95	0.296
11.55	144.08	0.296
11.56	144.21	0.296
11.57	144.35	0.297
11.59	144.48	0.297
11.60	144.61	0.297
11.61	144.75	0.297
11.63	144.88	0.298
11.64	145.01	0.298
11.65	145.15	0.298
11.67	145.28	0.298
11.68	145.41	0.299
11.69	145.55	0.299
11.71	145.68	0.300
11.72	145.81	0.301
11.73	145.95	0.302
11.75	146.08	0.302
11.76	146.21	0.302
11.77	146.35	0.302
11.79	146.48	0.303
11.80	146.61	0.303
11.81	146.75	0.303
11.83	146.88	0.303
11.84	147.01	0.304
11.85	147.15	0.304
11.87	147.28	0.304
11.88	147.41	0.305
11.89	147.55	0.305
11.91	147.68	0.306
11.92	147.81	0.306
11.93	147.95	0.306
11.95	148.08	0.307
11.96	148.21	0.307
11.97	148.35	0.307
11.99	148.48	0.308
12.00	148.61	0.309
12.01	148.75	0.309
12.03	148.88	0.311
12.04	149.01	0.311
12.05	149.15	0.312
12.07	149.28	0.313
12.08	149.41	0.315
12.09	149.55	0.317
12.11	149.68	0.319
12.12	149.81	0.321
12.13	149.94	0.323
12.15	150.08	0.324
12.16	150.21	0.329
12.17	150.34	0.333
12.19	150.48	0.337
12.20	150.61	0.341
12.21	150.74	0.345
12.23	150.87	0.349
12.24	151.01	0.354
12.25	151.14	0.359
12.27	151.27	0.366
12.28	151.41	0.371
12.29	151.54	0.378
12.31	151.67	0.385
12.32	151.80	0.393
12.33	151.94	0.399
12.35	152.07	0.407
12.36	152.20	0.417
12.37	152.33	0.423
12.39	152.46	0.430
12.40	152.60	0.437
12.41	152.73	0.449
12.43	152.86	0.459
12.44	152.99	0.467
12.45	153.13	0.474
12.47	153.26	0.483
12.48	153.39	0.494
12.49	153.52	0.499
12.51	153.65	0.510
12.52	153.78	0.518
12.53	153.92	0.526
12.55	154.05	0.536
12.56	154.18	0.541
12.57	154.31	0.552
12.59	154.44	0.559
12.60	154.57	0.558
12.61	154.71	0.555
12.63	154.84	0.562
12.64	154.97	0.574
12.65	155.10	0.585
12.67	155.24	0.593
12.68	155.37	0.600
12.69	155.50	0.608
12.71	155.63	0.612
12.72	155.76	0.619
12.73	155.90	0.623
12.75	156.03	0.628
12.76	156.16	0.633
12.77	156.29	0.638
12.79	156.43	0.641
12.80	156.56	0.644
12.81	156.69	0.646
12.83	156.82	0.649
12.84	156.96	0.651
12.85	157.09	0.653
12.87	157.22	0.653
12.88	157.36	0.655
12.89	157.49	0.656
12.91	157.62	0.657
12.92	157.75	0.657
12.93	157.89	0.657
12.95	158.02	0.658
12.96	158.15	0.658
12.97	158.29	0.659
12.99	158.42	0.659
13.00	158.55	0.659
13.01	158.69	0.659
13.03	158.82	0.659
13.04	158.95	0.659
13.05	159.09	0.659
13.07	159.22	0.659
13.08	159.35	0.659
13.09	159.49	0.659
13.11	159.62	0.658
13.12	159.76	0.657
13.13	159.89	0.657
13.15	160.02	0.656
13.16	160.16	0.655
13.17	160.29	0.654
13.19	160.42	0.653
13.20	160.56	0.652
13.21	160.69	0.650
13.23	160.83	0.649
13.24	160.96	0.646
13.25	161.09	0.645
13.27	161.23	0.644
13.28	161.36	0.642
13.29	161.49	0.641
13.31	161.63	0.641
13.32	161.76	0.639
13.33	161.89	0.638
13.35	162.03	0.637
13.36	162.16	0.637
13.37	162.30	0.635
13.39	162.43	0.634
13.40	162.56	0.633
13.41	162.70	0.632
13.43	162.83	0.631
13.44	162.96	0.630
13.45	163.10	0.629
13.47	163.23	0.629
13.48	163.36	0.628
13.49	163.50	0.628
13.51	163.63	0.627
13.52	163.76	0.626
13.53	163.90	0.626
13.55	164.03	0.625
13.56	164.17	0.625
13.57	164.30	0.624
13.59	164.43	0.624
13.60	164.57	0.623
13.61	164.70	0.623
13.63	164.83	0.622
13.64	164.97	0.622
13.65	165.10	0.621
13.67	165.23	0.621
13.68	165.37	0.620
13.69	165.50	0.620
13.71	165.63	0.620
13.72	165.77	0.619
13.73	165.90	0.619
13.75	166.03	0.618
13.76	166.17	0.618
13.77	166.30	0.618
13.79	166.43	0.618
13.80	166.57	0.617
13.81	166.70	0.617
13.83	166.84	0.617
13.84	166.97	0.617
13.85	167.10	0.617
13.87	167.23	0.617
13.88	167.37	0.617
13.89	167.50	0.617
13.91	167.64	0.617
13.92	167.77	0.617
13.93	167.90	0.617
13.95	168.04	0.617
13.96	168.17	0.617
13.97	168.30	0.617
13.99	168.44	0.617
14.00	168.57	0.617
14.01	168.70	0.617
14.03	168.83	0.617
14.04	168.97	0.617
14.05	169.10	0.618
14.07	169.23	0.618
14.08	169.37	0.618
14.09	169.50	0.619
14.11	169.63	0.620
14.12	169.77	0.620
14.13	169.90	0.622
14.15	170.03	0.623
14.16	170.17	0.624
14.17	170.30	0.625
14.19	170.43	0.627
14.20	170.57	0.628
14.21	170.70	0.629
14.23	170.83	0.629
14.24	170.97	0.630
14.25	171.10	0.631
14.27	171.23	0.633
14.28	171.37	0.635
14.29	171.50	0.637
14.31	171.63	0.638
14.32	171.76	0.640
14.33	171.90	0.643
14.35	172.03	0.644
14.36	172.16	0.646
14.37	172.30	0.649
14.39	172.43	0.651
14.40	172.56	0.654
14.41	172.70	0.657
14.43	172.83	0.659
14.44	172.96	0.661
14.45	173.10	0.664
14.47	173.23	0.667
14.48	173.36	0.671
14.49	173.49	0.673
14.51	173.63	0.677
14.52	173.76	0.679
14.53	173.89	0.681
14.55	174.03	0.682
14.56	174.16	0.683
14.57	174.29	0.686
14.59	174.43	0.693
14.60	174.56	0.699
14.61	174.69	0.704
14.63	174.82	0.706
14.64	174.96	0.710
14.65	175.09	0.712
14.67	175.22	0.716
14.68	175.36	0.719
14.69	175.49	0.724
14.71	175.62	0.728
14.72	175.75	0.732
14.73	175.89	0.737
14.75	176.02	0.741
14.76	176.15	0.747
14.77	176.28	0.751
14.79	176.42	0.755
14.80	176.55	0.757
14.81	176.68	0.762
14.83	176.82	0.766
14.84	176.95	0.769
14.85	177.08	0.775
14.87	177.21	0.779
14.88	177.35	0.785
14.89	177.48	0.796
14.91	177.61	0.801
14.92	177.74	0.801
14.93	177.88	0.802
14.95	178.01	0.802
14.96	178.14	0.803
14.97	178.27	0.808
14.99	178.41	0.816
15.00	178.54	0.817
15.01	178.67	0.816
15.03	178.81	0.821
15.04	178.94	0.831
15.05	179.07	0.843
15.07	179.20	0.849
15.08	179.34	0.857
15.09	179.47	0.865
15.11	179.60	0.872
15.12	179.73	0.879
15.13	179.86	0.886
15.15	180.00	0.892
15.16	180.13	0.899
15.17	180.26	0.905
15.19	180.39	0.913
15.20	180.53	0.921
15.21	180.66	0.928
15.23	180.79	0.934
15.24	180.92	0.941
15.25	181.05	0.954
15.27	181.19	0.963
15.28	181.32	0.972
15.29	181.45	0.981
15.31	181.58	0.988
15.32	181.71	0.996
15.33	181.85	1.005
15.35	181.98	1.012
15.36	182.11	1.021
15.37	182.24	1.030
15.39	182.37	1.040
15.40	182.51	1.048
15.41	182.64	1.058
15.43	182.77	1.069
15.44	182.90	1.083
15.45	183.03	1.093
15.47	183.16	1.102
15.48	183.29	1.118
15.49	183.43	1.129
15.51	183.56	1.145
15.52	183.69	1.165
15.53	183.82	1.182
15.55	183.95	1.192
15.56	184.08	1.201
15.57	184.21	1.211
15.59	184.34	1.222
15.60	184.48	1.236
15.61	184.61	1.252
15.63	184.74	1.265
15.64	184.87	1.284
15.65	185.00	1.298
15.67	185.13	1.311
15.68	185.26	1.339
15.69	185.39	1.380
15.71	185.52	1.425
15.72	185.65	1.458
15.73	185.78	1.471
15.75	185.91	1.479
15.76	186.04	1.499
15.77	186.16	1.536
15.79	186.29	1.571
15.80	186.42	1.581
15.81	186.55	1.586
15.83	186.68	1.592
15.84	186.81	1.606
15.85	186.94	1.626
15.87	187.07	1.642
15.88	187.21	1.666
15.89	187.33	1.682
15.91	187.47	1.698
15.92	187.60	1.711
15.93	187.73	1.722
15.95	187.86	1.737
15.96	187.99	1.750
15.97	188.12	1.764
15.99	188.25	1.780
16.00	188.38	1.793
16.01	188.51	1.806
16.03	188.64	1.826
16.04	188.78	1.841
16.05	188.91	1.859
16.07	189.04	1.867
16.08	189.17	1.875
16.09	189.30	1.881
16.11	189.43	1.891
16.12	189.56	1.904
16.13	189.69	1.917
16.15	189.82	1.929
16.16	189.95	1.947
16.17	190.09	1.961
16.19	190.22	1.983
16.20	190.35	1.999
16.21	190.48	2.002
16.23	190.61	1.992
16.24	190.74	1.979
16.25	190.88	1.957
16.27	191.01	1.923
16.28	191.15	1.885
16.29	191.29	1.818
16.31	191.42	1.737
16.32	191.57	1.619
16.33	191.71	1.468
16.35	191.86	1.304
16.36	192.02	1.154
16.37	192.17	1.023
16.39	192.32	0.912
16.40	192.48	0.809
16.41	192.63	0.734
16.43	192.78	0.680
16.44	192.93	0.646
16.45	193.07	0.615
16.47	193.22	0.590
16.48	193.36	0.572
16.49	193.50	0.555
16.51	193.64	0.540
16.52	193.78	0.529
16.53	193.92	0.520
16.55	194.05	0.512
16.56	194.19	0.503
16.57	194.33	0.499
16.59	194.46	0.492
16.60	194.60	0.491
16.61	194.73	0.485
16.63	194.87	0.483
16.64	195.00	0.480
16.65	195.14	0.477
16.67	195.27	0.476
16.68	195.41	0.475
16.69	195.54	0.474
16.71	195.67	0.473
16.72	195.81	0.472
16.73	195.94	0.471
16.75	196.07	0.471
16.76	196.21	0.471
16.77	196.34	0.470
16.79	196.47	0.470
16.80	196.61	0.470
16.81	196.74	0.469
16.83	196.88	0.469
16.84	197.01	0.469
16.85	197.14	0.469
16.87	197.28	0.469
16.88	197.41	0.469
16.89	197.54	0.468
16.91	197.68	0.468
16.92	197.81	0.468
16.93	197.94	0.468
16.95	198.08	0.468
16.96	198.21	0.468
16.97	198.34	0.468
16.99	198.47	0.468
17.00	198.61	0.468
17.01	198.74	0.468
17.03	198.88	0.468
17.04	199.01	0.468
17.05	199.14	0.468
17.07	199.28	0.468
17.08	199.41	0.468
17.09	199.54	0.468
17.11	199.68	0.468
17.12	199.81	0.468
17.13	199.94	0.468
17.15	200.08	0.468
17.16	200.21	0.468
17.17	200.34	0.468
17.19	200.48	0.469
17.20	200.61	0.469
17.21	200.74	0.469
17.23	200.88	0.469
17.24	201.01	0.469
17.25	201.14	0.469
17.27	201.28	0.469
17.28	201.41	0.470
17.29	201.54	0.470
17.31	201.68	0.470
17.32	201.81	0.470
17.33	201.94	0.470
17.35	202.08	0.471
17.36	202.21	0.471
17.37	202.34	0.471
17.39	202.48	0.471
17.40	202.61	0.471
17.41	202.74	0.472
17.43	202.88	0.472
17.44	203.01	0.472
17.45	203.14	0.472
17.47	203.28	0.473
17.48	203.41	0.473
17.49	203.54	0.473
17.51	203.68	0.474
17.52	203.81	0.474
17.53	203.94	0.474
17.55	204.08	0.475
17.56	204.21	0.475
17.57	204.34	0.475
17.59	204.48	0.475
17.60	204.61	0.476
17.61	204.74	0.476
17.63	204.88	0.476
17.64	205.01	0.476
17.65	205.14	0.476
17.67	205.28	0.477
17.68	205.41	0.477
17.69	205.54	0.477
17.71	205.68	0.477
17.72	205.81	0.477
17.73	205.94	0.478
17.75	206.08	0.478
17.76	206.21	0.478
17.77	206.34	0.478
17.79	206.48	0.478
17.80	206.61	0.479
17.81	206.74	0.479
17.83	206.88	0.479
17.84	207.01	0.479
17.85	207.14	0.480
17.87	207.28	0.480
17.88	207.41	0.480
17.89	207.54	0.480
17.91	207.68	0.480
17.92	207.81	0.480
17.93	207.94	0.479
17.95	208.08	0.479
17.96	208.21	0.479
17.97	208.35	0.479
17.99	208.48	0.479
18.00	208.61	0.479
18.00	208.63	0.479

[step]
Ramp 10.00 °C/min to 30.00 °C
Time	Temperature	Heat Flow (Normalized)
min	°C	W/g
19.00	210.07	-0.065
19.02	210.07	-0.063
19.03	210.07	-0.062
19.04	210.06	-0.060
19.06	210.06	-0.057
19.07	210.04	-0.054
19.08	210.02	-0.053
19.10	209.99	-0.054
19.11	209.94	-0.076
19.12	209.89	-0.109
19.14	209.82	-0.147
19.15	209.74	-0.187
19.16	209.65	-0.235
19.18	209.56	-0.276
19.19	209.46	-0.318
19.20	209.35	-0.353
19.22	209.24	-0.382
19.23	209.13	-0.410
19.24	209.01	-0.429
19.26	208.89	-0.449
19.27	208.77	-0.464
19.28	208.65	-0.477
19.30	208.53	-0.487
19.31	208.40	-0.496
19.32	208.28	-0.505
19.34	208.15	-0.508
19.35	208.02	-0.516
19.36	207.90	-0.520
19.38	207.77	-0.521
19.39	207.64	-0.526
19.40	207.51	-0.530
19.42	207.38	-0.532
19.43	207.25	-0.534
19.44	207.12	-0.536
19.46	206.99	-0.537
19.47	206.86	-0.539
19.48	206.73	-0.540
19.50	206.60	-0.541
19.51	206.47	-0.542
19.52	206.34	-0.542
19.54	206.21	-0.543
19.55	206.08	-0.543
19.56	205.94	-0.544
19.58	205.81	-0.544
19.59	205.68	-0.545
19.60	205.55	-0.545
19.62	205.42	-0.546
19.63	205.29	-0.546
19.64	205.16	-0.546
19.66	205.02	-0.547
19.67	204.89	-0.547
19.68	204.76	-0.547
19.70	204.63	-0.547
19.71	204.50	-0.547
19.72	204.37	-0.547
19.74	204.23	-0.547
19.75	204.10	-0.542
19.76	203.97	-0.534
19.78	203.84	-0.533
19.79	203.70	-0.533
19.80	203.57	-0.533
19.82	203.44	-0.533
19.83	203.31	-0.533
19.84	203.17	-0.533
19.86	203.04	-0.533
19.87	202.91	-0.533
19.88	202.78	-0.533
19.90	202.64	-0.533
19.91	202.51	-0.533
19.92	202.38	-0.533
19.94	202.25	-0.533
19.95	202.11	-0.533
19.96	201.98	-0.532
19.98	201.85	-0.532
19.99	201.72	-0.532
20.00	201.58	-0.531
20.02	201.45	-0.531
20.03	201.32	-0.530
20.04	201.19	-0.530
20.06	201.05	-0.528
20.07	200.92	-0.528
20.08	200.79	-0.526
20.10	200.65	-0.526
20.11	200.52	-0.525
20.12	200.39	-0.523
20.14	200.26	-0.522
20.15	200.12	-0.520
20.16	199.99	-0.518
20.18	199.86	-0.516
20.19	199.72	-0.514
20.20	199.59	-0.512
20.22	199.46	-0.509
20.23	199.32	-0.508
20.24	199.19	-0.506
20.26	199.06	-0.505
20.27	198.93	-0.503
20.28	198.79	-0.502
20.30	198.66	-0.499
20.31	198.53	-0.499
20.32	198.39	-0.498
20.34	198.26	-0.497
20.35	198.13	-0.496
20.36	197.99	-0.495
20.38	197.86	-0.495
20.39	197.73	-0.493
20.40	197.59	-0.493
20.42	197.46	-0.493
20.43	197.33	-0.493
20.44	197.19	-0.492
20.46	197.06	-0.492
20.47	196.93	-0.493
20.48	196.80	-0.493
20.50	196.66	-0.494
20.51	196.53	-0.495
20.52	196.40	-0.497
20.54	196.26	-0.498
20.55	196.13	-0.500
20.56	196.00	-0.502
20.58	195.87	-0.504
20.59	195.73	-0.506
20.60	195.60	-0.508
20.62	195.47	-0.510
20.63	195.34	-0.512
20.64	195.20	-0.514
20.66	195.07	-0.516
20.67	194.94	-0.517
20.68	194.80	-0.519
20.70	194.67	-0.521
20.71	194.54	-0.522
20.72	194.41	-0.524
20.74	194.27	-0.526
20.75	194.14	-0.527
20.76	194.01	-0.530
20.78	193.88	-0.531
20.79	193.74	-0.531
20.80	193.61	-0.533
20.82	193.48	-0.533
20.83	193.34	-0.535
20.84	193.21	-0.536
20.86	193.08	-0.537
20.87	192.95	-0.538
20.88	192.81	-0.539
20.90	192.68	-0.541
20.91	192.55	-0.542
20.92	192.42	-0.542
20.94	192.28	-0.543
20.95	192.15	-0.545
20.96	192.02	-0.546
20.98	191.88	-0.546
20.99	191.75	-0.547
21.00	191.62	-0.548
21.02	191.49	-0.550
21.03	191.35	-0.550
21.04	191.22	-0.551
21.06	191.09	-0.552
21.07	190.95	-0.553
21.08	190.82	-0.554
21.10	190.69	-0.554
21.11	190.55	-0.555
21.12	190.42	-0.556
21.14	190.29	-0.556
21.15	190.16	-0.557
21.16	190.02	-0.558
21.18	189.89	-0.559
21.19	189.76	-0.559
21.20	189.62	-0.560
21.22	189.49	-0.561
21.23	189.36	-0.562
21.24	189.22	-0.563
21.26	189.09	-0.564
21.27	188.96	-0.564
21.28	188.83	-0.565
21.30	188.69	-0.566
21.31	188.56	-0.566
21.32	188.43	-0.567
21.34	188.29	-0.567
21.35	188.16	-0.568
21.36	188.03	-0.568
21.38	187.89	-0.569
21.39	187.76	-0.570
21.40	187.63	-0.571
21.42	187.50	-0.571
21.43	187.36	-0.572
21.44	187.23	-0.572
21.46	187.10	-0.573
21.47	186.96	-0.574
21.48	186.83	-0.574
21.50	186.70	-0.575
21.51	186.56	-0.575
21.52	186.43	-0.576
21.54	186.30	-0.576
21.55	186.17	-0.577
21.56	186.03	-0.578
21.58	185.90	-0.578
21.59	185.77	-0.579
21.60	185.63	-0.579
21.62	185.50	-0.580
21.63	185.37	-0.580
21.64	185.23	-0.581
21.66	185.10	-0.582
21.67	184.97	-0.582
21.68	184.83	-0.583
21.70	184.70	-0.584
21.71	184.57	-0.585
21.72	184.43	-0.585
21.74	184.30	-0.586
21.75	184.17	-0.586
21.76	184.04	-0.586
21.78	183.90	-0.587
21.79	183.77	-0.587
21.80	183.64	-0.588
21.82	183.50	-0.588
21.83	183.37	-0.589
21.84	183.24	-0.589
21.86	183.10	-0.590
21.87	182.97	-0.590
21.88	182.84	-0.591
21.90	182.70	-0.591
21.91	182.57	-0.591
21.92	182.44	-0.592
21.94	182.31	-0.592
21.95	182.17	-0.593
21.96	182.04	-0.593
21.98	181.91	-0.594
21.99	181.77	-0.594
22.00	181.64	-0.594
22.02	181.51	-0.595
22.03	181.37	-0.595
22.04	181.24	-0.596
22.06	181.11	-0.596
22.07	180.97	-0.596
22.08	180.84	-0.597
22.10	180.71	-0.597
22.11	180.57	-0.597
22.12	180.44	-0.598
22.14	180.31	-0.598
22.15	180.17	-0.598
22.16	180.04	-0.599
22.18	179.91	-0.599
22.19	179.78	-0.599
22.20	179.64	-0.600
22.22	179.51	-0.600
22.23	179.38	-0.600
22.24	179.24	-0.601
22.26	179.11	-0.601
22.27	178.98	-0.601
22.28	178.84	-0.602
22.30	178.71	-0.602
22.31	178.58	-0.602
22.32	178.44	-0.603
22.34	178.31	-0.603
22.35	178.18	-0.603
22.36	178.04	-0.604
22.38	177.91	-0.604
22.39	177.78	-0.604
22.40	177.65	-0.604
22.42	177.51	-0.605
22.43	177.38	-0.605
22.44	177.25	-0.605
22.46	177.11	-0.605
22.47	176.98	-0.606
22.48	176.85	-0.606
22.50	176.71	-0.606
22.51	176.58	-0.606
22.52	176.45	-0.607
22.54	176.31	-0.607
22.55	176.18	-0.607
22.56	176.05	-0.607
22.58	175.91	-0.608
22.59	175.78	-0.608
22.60	175.65	-0.608
22.62	175.52	-0.608
22.63	175.38	-0.608
22.64	175.25	-0.609
22.66	175.12	-0.609
22.67	174.98	-0.609
22.68	174.85	-0.609
22.70	174.72	-0.609
22.71	174.58	-0.610
22.72	174.45	-0.610
22.74	174.32	-0.610
22.75	174.18	-0.610
22.76	174.05	-0.610
22.78	173.92	-0.611
22.79	173.78	-0.611
22.80	173.65	-0.611
22.82	173.52	-0.611
22.83	173.39	-0.611
22.84	173.25	-0.611
22.86	173.12	-0.612
22.87	172.99	-0.612
22.88	172.85	-0.612
22.90	172.72	-0.612
22.91	172.59	-0.612
22.92	172.45	-0.612
22.94	172.32	-0.613
22.95	172.19	-0.613
22.96	172.05	-0.613
22.98	171.92	-0.613
22.99	171.79	-0.613
23.00	171.65	-0.613
23.02	171.52	-0.614
23.03	171.39	-0.614
23.04	171.25	-0.614
23.06	171.12	-0.614
23.07	170.99	-0.614
23.08	170.85	-0.614
23.10	170.72	-0.614
23.11	170.59	-0.614
23.12	170.46	-0.614
23.14	170.32	-0.614
23.15	170.19	-0.614
23.16	170.06	-0.615
23.18	169.92	-0.615
23.19	169.79	-0.615
23.20	169.66	-0.615
23.22	169.52	-0.615
23.23	169.39	-0.615
23.24	169.26	-0.615
23.26	169.12	-0.615
23.27	168.99	-0.615
23.28	168.86	-0.615
23.30	168.72	-0.616
23.31	168.59	-0.616
23.32	168.46	-0.616
23.34	168.33	-0.616
23.35	168.19	-0.616
23.36	168.06	-0.616
23.38	167.93	-0.616
23.39	167.79	-0.616
23.40	167.66	-0.616
23.42	167.53	-0.616
23.43	167.39	-0.616
23.44	167.26	-0.616
23.46	167.13	-0.616
23.47	166.99	-0.616
23.48	166.86	-0.616
23.50	166.73	-0.616
23.51	166.59	-0.617
23.52	166.46	-0.617
23.54	166.33	-0.617
23.55	166.19	-0.617
23.56	166.06	-0.617
23.58	165.93	-0.617
23.59	165.79	-0.617
23.60	165.66	-0.617
23.62	165.53	-0.617
23.63	165.39	-0.617
23.64	165.26	-0.617
23.66	165.13	-0.617
23.67	165.00	-0.617
23.68	164.86	-0.617
23.70	164.73	-0.617
23.71	164.60	-0.617
23.72	164.46	-0.617
23.74	164.33	-0.617
23.75	164.20	-0.617
23.76	164.06	-0.617
23.78	163.93	-0.617
23.79	163.80	-0.617
23.80	163.66	-0.617
23.82	163.53	-0.617
23.83	163.40	-0.617
23.84	163.26	-0.617
23.86	163.13	-0.617
23.87	163.00	-0.617
23.88	162.86	-0.617
23.90	162.73	-0.617
23.91	162.60	-0.617
23.92	162.46	-0.617
23.94	162.33	-0.617
23.95	162.20	-0.617
23.96	162.07	-0.617
23.98	161.93	-0.617
23.99	161.80	-0.617
24.00	161.67	-0.617
24.02	161.53	-0.617
24.03	161.40	-0.617
24.04	161.27	-0.617
24.06	161.13	-0.617
24.07	161.00	-0.617
24.08	160.87	-0.617
24.10	160.73	-0.617
24.11	160.60	-0.617
24.12	160.47	-0.617
24.14	160.34	-0.617
24.15	160.20	-0.617
24.16	160.07	-0.617
24.18	159.93	-0.616
24.19	159.80	-0.616
24.20	159.67	-0.616
24.22	159.54	-0.616
24.23	159.40	-0.616
24.24	159.27	-0.616
24.26	159.13	-0.616
24.27	159.00	-0.616
24.28	158.87	-0.616
24.30	158.74	-0.616
24.31	158.60	-0.616
24.32	158.47	-0.616
24.34	158.34	-0.616
24.35	158.20	-0.616
24.36	158.07	-0.616
24.38	157.94	-0.616
24.39	157.80	-0.616
24.40	157.67	-0.616
24.42	157.54	-0.616
24.43	157.40	-0.616
24.44	157.27	-0.616
24.46	157.14	-0.615
24.47	157.00	-0.615
24.48	156.87	-0.615
24.50	156.74	-0.615
24.51	156.60	-0.615
24.52	156.47	-0.615
24.54	156.34	-0.615
24.55	156.20	-0.615
24.56	156.07	-0.615
24.58	155.94	-0.615
24.59	155.80	-0.615
24.60	155.67	-0.615
24.62	155.54	-0.615
24.63	155.41	-0.615
24.64	155.27	-0.614
24.66	155.14	-0.614
24.67	155.01	-0.614
24.68	154.87	-0.614
24.70	154.74	-0.614
24.71	154.61	-0.614
24.72	154.47	-0.614
24.74	154.34	-0.614
24.75	154.21	-0.614
24.76	154.07	-0.614
24.78	153.94	-0.614
24.79	153.81	-0.614
24.80	153.67	-0.614
24.82	153.54	-0.614
24.83	153.41	-0.614
24.84	153.28	-0.614
24.86	153.14	-0.614
24.87	153.01	-0.614
24.88	152.88	-0.613
24.90	152.74	-0.613
24.91	152.61	-0.613
24.92	152.48	-0.613
24.94	152.34	-0.613
24.95	152.21	-0.613
24.96	152.08	-0.613
24.98	151.94	-0.613
24.99	151.81	-0.613
25.00	151.68	-0.613
25.02	151.54	-0.613
25.03	151.41	-0.612
25.04	151.28	-0.612
25.06	151.14	-0.612
25.07	151.01	-0.612
25.08	150.88	-0.612
25.10	150.74	-0.612
25.11	150.61	-0.612
25.12	150.48	-0.612
25.14	150.34	-0.612
25.15	150.21	-0.612
25.16	150.08	-0.611
25.18	149.94	-0.611
25.19	149.81	-0.611
25.20	149.68	-0.611
25.22	149.54	-0.611
25.23	149.41	-0.611
25.24	149.28	-0.611
25.26	149.15	-0.611
25.27	149.01	-0.611
25.28	148.88	-0.610
25.30	148.75	-0.610
25.31	148.61	-0.610
25.32	148.48	-0.610
25.34	148.35	-0.610
25.35	148.21	-0.610
25.36	148.08	-0.610
25.38	147.95	-0.610
25.39	147.81	-0.610
25.40	147.68	-0.610
25.42	147.55	-0.609
25.43	147.41	-0.609
25.44	147.28	-0.609
25.46	147.15	-0.609
25.47	147.01	-0.609
25.48	146.88	-0.609
25.50	146.75	-0.609
25.51	146.61	-0.609
25.52	146.48	-0.609
25.54	146.35	-0.608
25.55	146.21	-0.608
25.56	146.08	-0.608
25.58	145.95	-0.608
25.59	145.82	-0.608
25.60	145.68	-0.608
25.62	145.55	-0.608
25.63	145.42	-0.607
25.64	145.28	-0.607
25.66	145.15	-0.607
25.67	145.02	-0.607
25.68	144.88	-0.607
25.70	144.75	-0.607
25.71	144.62	-0.607
25.72	144.48	-0.607
25.74	144.35	-0.607
25.75	144.22	-0.607
25.76	144.08	-0.606
25.78	143.95	-0.606
25.79	143.82	-0.606
25.80	143.68	-0.606
25.82	143.55	-0.606
25.83	143.42	-0.606
25.84	143.28	-0.606
25.86	143.15	-0.606
25.87	143.02	-0.605
25.88	142.88	-0.605
25.90	142.75	-0.605
25.91	142.62	-0.605
25.92	142.48	-0.605
25.94	142.35	-0.605
25.95	142.22	-0.605
25.96	142.08	-0.605
25.98	141.95	-0.605
25.99	141.82	-0.604
26.00	141.68	-0.604
26.02	141.55	-0.604
26.03	141.42	-0.604
26.04	141.29	-0.604
26.06	141.15	-0.604
26.07	141.02	-0.604
26.08	140.88	-0.603
26.10	140.75	-0.603
[...]
41.79	66.44	0.411
41.80	66.57	0.411
41.82	66.70	0.412
41.83	66.84	0.412
41.84	66.97	0.412
41.86	67.10	0.412
41.87	67.24	0.412
41.88	67.37	0.413
41.90	67.50	0.413
41.91	67.64	0.413
41.92	67.77	0.413
41.94	67.90	0.413
41.95	68.04	0.413
41.96	68.17	0.414
41.98	68.30	0.414
41.99	68.44	0.414
42.00	68.57	0.414
42.02	68.70	0.414
42.03	68.84	0.415
42.04	68.97	0.415
42.06	69.11	0.415
42.07	69.24	0.415
42.08	69.37	0.415
42.10	69.50	0.415
42.11	69.64	0.416
42.12	69.77	0.416
42.14	69.91	0.416
42.15	70.04	0.416
42.16	70.17	0.416
42.18	70.31	0.417
42.19	70.44	0.417
42.20	70.57	0.417
42.22	70.71	0.417
42.23	70.84	0.417
42.24	70.97	0.417
42.26	71.11	0.418
42.27	71.24	0.418
42.28	71.37	0.418
42.30	71.51	0.418
42.31	71.64	0.418
42.32	71.77	0.419
42.34	71.91	0.419
42.35	72.04	0.419
42.36	72.17	0.419
42.38	72.31	0.419
42.39	72.44	0.420
42.40	72.57	0.420
42.42	72.71	0.420
42.43	72.84	0.420
42.44	72.97	0.420
42.46	73.11	0.421
42.47	73.24	0.421
42.48	73.37	0.421
42.50	73.51	0.421
42.51	73.64	0.421
42.52	73.78	0.422
42.54	73.91	0.422
42.55	74.04	0.422
42.56	74.17	0.422
42.58	74.31	0.422
42.59	74.44	0.422
42.60	74.57	0.423
42.62	74.71	0.423
42.63	74.84	0.423
42.64	74.98	0.423
42.66	75.11	0.423
42.67	75.24	0.424
42.68	75.38	0.424
42.70	75.51	0.424
42.71	75.64	0.424
42.72	75.78	0.425
42.74	75.91	0.425
42.75	76.04	0.425
42.76	76.18	0.425
42.78	76.31	0.425
42.79	76.44	0.425
42.80	76.58	0.426
42.82	76.71	0.426
42.83	76.84	0.426
42.84	76.98	0.426
42.86	77.11	0.426
42.87	77.24	0.427
42.88	77.38	0.427
42.90	77.51	0.427
42.91	77.64	0.427
42.92	77.78	0.427
42.94	77.91	0.428
42.95	78.04	0.428
42.96	78.18	0.428
42.98	78.31	0.428
42.99	78.44	0.429
43.00	78.58	0.429
43.02	78.71	0.429
43.03	78.84	0.429
43.04	78.98	0.429
43.06	79.11	0.430
43.07	79.24	0.430
43.08	79.38	0.430
43.10	79.51	0.430
43.11	79.65	0.430
43.12	79.78	0.431
43.14	79.91	0.431
43.15	80.04	0.431
43.16	80.18	0.431
43.18	80.31	0.431
43.19	80.45	0.432
43.20	80.58	0.432
43.22	80.71	0.432
43.23	80.85	0.432
43.24	80.98	0.432
43.26	81.11	0.432
43.27	81.25	0.433
43.28	81.38	0.433
43.30	81.51	0.433
43.31	81.65	0.433
43.32	81.78	0.433
43.34	81.91	0.433
43.35	82.05	0.434
43.36	82.18	0.434
43.38	82.31	0.434
43.39	82.45	0.434
43.40	82.58	0.434
43.42	82.71	0.434
43.43	82.85	0.435
43.44	82.98	0.435
43.46	83.11	0.435
43.47	83.25	0.435
43.48	83.38	0.435
43.50	83.51	0.435
43.51	83.65	0.436
43.52	83.78	0.436
43.54	83.91	0.436
43.55	84.05	0.436
43.56	84.18	0.436
43.58	84.31	0.437
43.59	84.45	0.437
43.60	84.58	0.437
43.62	84.72	0.437
43.63	84.85	0.437
43.64	84.98	0.437
43.66	85.12	0.438
43.67	85.25	0.438
43.68	85.38	0.438
43.70	85.52	0.438
43.71	85.65	0.438
43.72	85.78	0.438
43.74	85.91	0.439
43.75	86.05	0.439
43.76	86.18	0.439
43.78	86.31	0.439
43.79	86.45	0.439
43.80	86.58	0.439
43.82	86.71	0.439
43.83	86.85	0.440
43.84	86.98	0.440
43.86	87.12	0.440
43.87	87.25	0.440
43.88	87.38	0.440
43.90	87.52	0.441
43.91	87.65	0.441
43.92	87.78	0.441
43.94	87.92	0.441
43.95	88.05	0.441
43.96	88.18	0.441
43.98	88.32	0.442
43.99	88.45	0.442
44.00	88.58	0.442
44.02	88.72	0.442
44.03	88.85	0.442
44.04	88.98	0.443
44.06	89.12	0.443
44.07	89.25	0.443
44.08	89.38	0.443
44.10	89.52	0.443
44.11	89.65	0.444
44.12	89.78	0.444
44.14	89.92	0.444
44.15	90.05	0.444
44.16	90.18	0.444
44.18	90.32	0.445
44.19	90.45	0.445
44.20	90.58	0.445
44.22	90.72	0.445
44.23	90.85	0.445
44.24	90.98	0.446
44.26	91.12	0.446
44.27	91.25	0.446
44.28	91.39	0.446
44.30	91.52	0.447
44.31	91.65	0.447
44.32	91.78	0.447
44.34	91.92	0.447
44.35	92.05	0.447
44.36	92.18	0.448
44.38	92.32	0.448
44.39	92.45	0.448
44.40	92.59	0.448
44.42	92.72	0.448
44.43	92.85	0.449
44.44	92.98	0.449
44.46	93.12	0.449
44.47	93.25	0.449
44.48	93.39	0.450
44.50	93.52	0.450
44.51	93.65	0.450
44.52	93.79	0.450
44.54	93.92	0.450
44.55	94.05	0.450
44.56	94.19	0.451
44.58	94.32	0.451
44.59	94.45	0.451
44.60	94.59	0.451
44.62	94.72	0.451
44.63	94.85	0.452
44.64	94.99	0.452
44.66	95.12	0.452
44.67	95.25	0.452
44.68	95.39	0.452
44.70	95.52	0.453
44.71	95.65	0.453
44.72	95.79	0.453
44.74	95.92	0.453
44.75	96.05	0.453
44.76	96.19	0.454
44.78	96.32	0.454
44.79	96.45	0.454
44.80	96.59	0.454
44.82	96.72	0.455
44.83	96.85	0.455
44.84	96.99	0.455
44.86	97.12	0.455
44.87	97.25	0.455
44.88	97.39	0.455
44.90	97.52	0.456
44.91	97.65	0.456
44.92	97.79	0.456
44.94	97.92	0.456
44.95	98.05	0.456
44.96	98.19	0.457
44.98	98.32	0.457
44.99	98.45	0.457
45.00	98.59	0.457
45.02	98.72	0.457
45.03	98.85	0.458
45.04	98.99	0.458
45.06	99.12	0.458
45.07	99.25	0.458
45.08	99.39	0.458
45.10	99.52	0.459
45.11	99.65	0.459
45.12	99.79	0.459
45.14	99.92	0.459
45.15	100.05	0.459
45.16	100.19	0.459
45.18	100.32	0.460
45.19	100.46	0.460
45.20	100.59	0.460
45.22	100.72	0.460
45.23	100.86	0.461
45.24	100.99	0.461
45.26	101.12	0.461
45.27	101.26	0.461
45.28	101.39	0.461
45.30	101.52	0.462
45.31	101.65	0.462
45.32	101.79	0.462
45.34	101.92	0.462
45.35	102.06	0.462
45.36	102.19	0.463
45.38	102.32	0.463
45.39	102.46	0.463
45.40	102.59	0.463
45.42	102.72	0.463
45.43	102.86	0.463
45.44	102.99	0.464
45.46	103.12	0.464
45.47	103.26	0.464
45.48	103.39	0.464
45.50	103.52	0.464
45.51	103.66	0.465
45.52	103.79	0.465
45.54	103.92	0.465
45.55	104.06	0.465
45.56	104.19	0.466
45.58	104.32	0.466
45.59	104.46	0.466
45.60	104.59	0.466
45.62	104.72	0.466
45.63	104.86	0.466
45.64	104.99	0.467
45.66	105.12	0.467
45.67	105.26	0.467
45.68	105.39	0.467
45.70	105.52	0.467
45.71	105.66	0.468
45.72	105.79	0.468
45.74	105.92	0.468
45.75	106.06	0.468
45.76	106.19	0.468
45.78	106.32	0.468
45.79	106.46	0.469
45.80	106.59	0.469
45.82	106.73	0.469
45.83	106.86	0.469
45.84	106.99	0.470
45.86	107.12	0.470
45.87	107.26	0.470
45.88	107.39	0.470
45.90	107.53	0.470
45.91	107.66	0.471
45.92	107.79	0.471
45.94	107.92	0.471
45.95	108.06	0.471
45.96	108.19	0.471
45.98	108.33	0.472
45.99	108.46	0.472
46.00	108.59	0.472
46.02	108.73	0.472
46.03	108.86	0.472
46.04	108.99	0.473
46.06	109.13	0.473
46.07	109.26	0.473
46.08	109.39	0.473
46.10	109.53	0.473
46.11	109.66	0.474
46.12	109.79	0.474
46.14	109.93	0.474
46.15	110.06	0.474
46.16	110.19	0.474
46.18	110.33	0.474
46.19	110.46	0.475
46.20	110.59	0.475
46.22	110.73	0.475
46.23	110.86	0.475
46.24	110.99	0.475
46.26	111.13	0.476
46.27	111.26	0.476
46.28	111.39	0.476
46.30	111.53	0.476
46.31	111.66	0.476
46.32	111.79	0.477
46.34	111.93	0.477
46.35	112.06	0.477
46.36	112.19	0.477
46.38	112.33	0.477
46.39	112.46	0.478
46.40	112.60	0.478
46.42	112.73	0.478
46.43	112.86	0.478
46.44	112.99	0.479
46.46	113.13	0.479
46.47	113.26	0.479
46.48	113.40	0.479
46.50	113.53	0.479
46.51	113.66	0.480
46.52	113.80	0.480
46.54	113.93	0.480
46.55	114.06	0.480
46.56	114.20	0.480
46.58	114.33	0.481
46.59	114.46	0.481
46.60	114.60	0.481
46.62	114.73	0.481
46.63	114.86	0.481
46.64	115.00	0.482
46.66	115.13	0.482
46.67	115.26	0.482
46.68	115.40	0.482
46.70	115.53	0.482
46.71	115.66	0.482
46.72	115.80	0.483
46.74	115.93	0.483
46.75	116.06	0.483
46.76	116.20	0.483
46.78	116.33	0.484
46.79	116.46	0.484
46.80	116.60	0.484
46.82	116.73	0.484
46.83	116.86	0.484
46.84	117.00	0.485
46.86	117.13	0.485
46.87	117.26	0.485
46.88	117.40	0.485
46.90	117.53	0.485
46.91	117.66	0.486
46.92	117.80	0.486
46.94	117.93	0.486
46.95	118.06	0.486
46.96	118.20	0.486
46.98	118.33	0.486
46.99	118.46	0.487
47.00	118.60	0.487
47.02	118.73	0.487
47.03	118.86	0.487
47.04	119.00	0.488
47.06	119.13	0.488
47.07	119.26	0.488
47.08	119.40	0.488
47.10	119.53	0.488
47.11	119.66	0.489
47.12	119.80	0.489
47.14	119.93	0.489
47.15	120.06	0.489
47.16	120.20	0.489
47.18	120.33	0.490
47.19	120.46	0.490
47.20	120.60	0.490
47.22	120.73	0.490
47.23	120.86	0.491
47.24	121.00	0.491
47.26	121.13	0.491
47.27	121.27	0.491
47.28	121.40	0.491
47.30	121.53	0.492
47.31	121.67	0.492
47.32	121.80	0.492
47.34	121.93	0.492
47.35	122.07	0.492
47.36	122.20	0.493
47.38	122.33	0.493
47.39	122.47	0.493
47.40	122.60	0.493
47.42	122.73	0.493
47.43	122.87	0.494
47.44	123.00	0.494
47.46	123.13	0.494
47.47	123.27	0.494
47.48	123.40	0.494
47.50	123.53	0.495
47.51	123.67	0.495
47.52	123.80	0.495
47.54	123.93	0.495
47.55	124.07	0.495
47.56	124.20	0.496
47.58	124.33	0.496
47.59	124.47	0.496
47.60	124.60	0.496
47.62	124.73	0.496
47.63	124.87	0.496
47.64	125.00	0.497
47.66	125.13	0.497
47.67	125.27	0.497
47.68	125.40	0.497
47.70	125.53	0.497
47.71	125.67	0.498
47.72	125.80	0.498
47.74	125.93	0.498
47.75	126.07	0.498
47.76	126.20	0.498
47.78	126.33	0.499
47.79	126.47	0.499
47.80	126.60	0.499
47.82	126.74	0.499
47.83	126.87	0.499
47.84	127.00	0.500
47.86	127.13	0.500
47.87	127.27	0.500
47.88	127.40	0.500
47.90	127.53	0.500
47.91	127.67	0.501
47.92	127.80	0.501
47.94	127.94	0.501
47.95	128.07	0.501
47.96	128.20	0.501
47.98	128.34	0.502
47.99	128.47	0.502
48.00	128.60	0.502
48.02	128.74	0.502
48.03	128.87	0.502
48.04	129.00	0.502
48.06	129.14	0.503
48.07	129.27	0.503
48.08	129.40	0.503
48.10	129.54	0.503
48.11	129.67	0.503
48.12	129.80	0.504
48.14	129.94	0.504
48.15	130.07	0.504
48.16	130.20	0.504
48.18	130.34	0.505
48.19	130.47	0.505
48.20	130.60	0.505
48.22	130.74	0.505
48.23	130.87	0.505
48.24	131.00	0.506
48.26	131.14	0.506
48.27	131.27	0.506
48.28	131.40	0.506
48.30	131.54	0.506
48.31	131.67	0.507
48.32	131.80	0.507
48.34	131.94	0.507
48.35	132.07	0.507
48.36	132.20	0.507
48.38	132.34	0.507
48.39	132.47	0.508
48.40	132.60	0.508
48.42	132.74	0.508
48.43	132.87	0.508
48.44	133.00	0.509
48.46	133.14	0.509
48.47	133.27	0.509
48.48	133.40	0.509
48.50	133.54	0.509
48.51	133.67	0.510
48.52	133.80	0.510
48.54	133.94	0.510
48.55	134.07	0.510
48.56	134.20	0.510
48.58	134.34	0.510
48.59	134.47	0.511
48.60	134.60	0.511
48.62	134.74	0.511
48.63	134.87	0.511
48.64	135.00	0.511
48.66	135.14	0.512
48.67	135.27	0.512
48.68	135.40	0.512
48.70	135.54	0.512
48.71	135.67	0.512
48.72	135.80	0.513
48.74	135.94	0.513
48.75	136.07	0.513
48.76	136.21	0.513
48.78	136.34	0.514
48.79	136.47	0.514
48.80	136.61	0.514
48.82	136.74	0.514
48.83	136.87	0.514
48.84	137.00	0.514
48.86	137.14	0.515
48.87	137.27	0.515
48.88	137.41	0.515
48.90	137.54	0.515
48.91	137.67	0.515
48.92	137.81	0.516
48.94	137.94	0.516
48.95	138.07	0.516
48.96	138.21	0.516
48.98	138.34	0.516
48.99	138.47	0.517
49.00	138.61	0.517
49.02	138.74	0.517
49.03	138.87	0.517
49.04	139.01	0.517
49.06	139.14	0.518
49.07	139.27	0.518
49.08	139.41	0.518
49.10	139.54	0.518
49.11	139.67	0.519
49.12	139.81	0.519
49.14	139.94	0.519
49.15	140.07	0.519
49.16	140.21	0.519
49.18	140.34	0.519
49.19	140.47	0.520
49.20	140.61	0.520
49.22	140.74	0.520
49.23	140.87	0.520
49.24	141.01	0.520
49.26	141.14	0.520
49.27	141.27	0.521
49.28	141.41	0.521
49.30	141.54	0.521
49.31	141.67	0.521
49.32	141.81	0.522
49.34	141.94	0.522
49.35	142.07	0.522
49.36	142.21	0.522
49.38	142.34	0.522
49.39	142.47	0.523
49.40	142.61	0.523
49.42	142.74	0.523
49.43	142.87	0.523
49.44	143.01	0.523
49.46	143.14	0.524
49.47	143.28	0.524
49.48	143.41	0.524
49.50	143.54	0.524
49.51	143.67	0.524
49.52	143.81	0.525
49.54	143.94	0.525
49.55	144.07	0.525
49.56	144.21	0.525
49.58	144.34	0.526
49.59	144.47	0.526
49.60	144.61	0.526
49.62	144.74	0.526
49.63	144.87	0.526
49.64	145.01	0.527
49.66	145.14	0.527
49.67	145.28	0.527
49.68	145.41	0.527
49.70	145.54	0.527
49.71	145.68	0.528
49.72	145.81	0.528
49.74	145.94	0.528
49.75	146.08	0.528
49.76	146.21	0.528
49.78	146.34	0.528
49.79	146.48	0.529
49.80	146.61	0.529
49.82	146.74	0.529
49.83	146.88	0.529
49.84	147.01	0.529
49.86	147.14	0.530
49.87	147.28	0.530
49.88	147.41	0.530
49.90	147.54	0.530
49.91	147.68	0.530
49.92	147.81	0.530
49.94	147.94	0.531
49.95	148.08	0.531
49.96	148.21	0.531
49.98	148.34	0.531
49.99	148.48	0.531
50.00	148.61	0.532
50.02	148.74	0.532
50.03	148.88	0.532
50.04	149.01	0.532
50.06	149.14	0.532
50.07	149.28	0.532
50.08	149.41	0.533
50.10	149.54	0.533
50.11	149.68	0.533
50.12	149.81	0.533
50.14	149.94	0.534
50.15	150.08	0.534
50.16	150.21	0.534
50.18	150.34	0.534
50.19	150.48	0.534
50.20	150.61	0.534
50.22	150.74	0.535
50.23	150.88	0.535
50.24	151.01	0.535
50.26	151.14	0.535
50.27	151.28	0.535
50.28	151.41	0.535
50.30	151.54	0.536
50.31	151.68	0.536
50.32	151.81	0.536
50.34	151.94	0.536
50.35	152.08	0.536
50.36	152.21	0.537
50.38	152.34	0.537
50.39	152.48	0.537
50.40	152.61	0.537
50.42	152.74	0.537
50.43	152.88	0.538
50.44	153.01	0.538
50.46	153.14	0.538
50.47	153.28	0.538
50.48	153.41	0.538
50.50	153.54	0.539
50.51	153.68	0.539
50.52	153.81	0.539
50.54	153.94	0.539
50.55	154.08	0.539
50.56	154.21	0.540
50.58	154.34	0.540
50.59	154.48	0.540
50.60	154.61	0.540
50.62	154.74	0.540
50.63	154.88	0.540
50.64	155.01	0.541
50.66	155.15	0.541
50.67	155.28	0.541
50.68	155.41	0.541
50.70	155.54	0.541
50.71	155.68	0.541
50.72	155.81	0.542
50.74	155.94	0.542
50.75	156.08	0.542
50.76	156.21	0.542
50.78	156.35	0.542
50.79	156.48	0.543
50.80	156.61	0.543
50.82	156.75	0.543
50.83	156.88	0.543
50.84	157.01	0.543
50.86	157.15	0.544
50.87	157.28	0.544
50.88	157.41	0.544
50.90	157.55	0.544
50.91	157.68	0.544
50.92	157.81	0.544
50.94	157.95	0.544
50.95	158.08	0.545
50.96	158.21	0.545
50.98	158.35	0.545
50.99	158.48	0.545
51.00	158.61	0.545
51.02	158.75	0.545
51.03	158.88	0.546
51.04	159.01	0.546
51.06	159.15	0.546
51.07	159.28	0.546
51.08	159.41	0.546
51.10	159.55	0.547
51.11	159.68	0.547
51.12	159.81	0.547
51.14	159.95	0.547
51.15	160.08	0.547
51.16	160.21	0.548
51.18	160.35	0.548
51.19	160.48	0.548
51.20	160.61	0.548
51.22	160.75	0.548
51.23	160.88	0.549
51.24	161.01	0.549
51.26	161.15	0.549
51.27	161.28	0.549
51.28	161.41	0.549
51.30	161.55	0.549
51.31	161.68	0.549
51.32	161.81	0.550
51.34	161.95	0.550
51.35	162.08	0.550
51.36	162.21	0.550
51.38	162.35	0.550
51.39	162.48	0.550
51.40	162.61	0.551
51.42	162.75	0.551
51.43	162.88	0.551
51.44	163.01	0.551
51.46	163.15	0.551
51.47	163.28	0.551
51.48	163.41	0.552
51.50	163.55	0.552
51.51	163.68	0.552
51.52	163.81	0.552
51.54	163.95	0.552
51.55	164.08	0.552
51.56	164.21	0.553
51.58	164.35	0.553
51.59	164.48	0.553
51.60	164.61	0.553
51.62	164.75	0.553
51.63	164.88	0.554
51.64	165.02	0.554
51.66	165.15	0.554
51.67	165.28	0.554
51.68	165.42	0.554
51.70	165.55	0.555
51.71	165.68	0.555
51.72	165.82	0.555
51.74	165.95	0.555
51.75	166.08	0.555
51.76	166.22	0.555
51.78	166.35	0.556
51.79	166.48	0.556
51.80	166.62	0.556
51.82	166.75	0.556
51.83	166.88	0.556
51.84	167.02	0.557
51.86	167.15	0.557
51.87	167.28	0.557
51.88	167.42	0.557
51.90	167.55	0.557
51.91	167.68	0.558
51.92	167.82	0.558
51.94	167.95	0.558
51.95	168.08	0.558
51.96	168.22	0.558
51.98	168.35	0.558
51.99	168.48	0.559
52.00	168.62	0.559
52.02	168.75	0.559
52.03	168.88	0.559
52.04	169.02	0.559
52.06	169.15	0.559
52.07	169.28	0.560
52.08	169.42	0.560
52.10	169.55	0.560
52.11	169.68	0.560
52.12	169.82	0.560
52.14	169.95	0.560
52.15	170.08	0.561
52.16	170.22	0.561
52.18	170.35	0.561
52.19	170.48	0.561
52.20	170.62	0.561
52.22	170.75	0.562
52.23	170.88	0.562
52.24	171.02	0.562
52.26	171.15	0.562
52.27	171.28	0.563
52.28	171.42	0.563
52.30	171.55	0.563
52.31	171.68	0.563
52.32	171.82	0.563
52.34	171.95	0.564
52.35	172.08	0.564
52.36	172.22	0.564
52.38	172.35	0.564
52.39	172.48	0.564
52.40	172.62	0.564
52.42	172.75	0.565
52.43	172.88	0.565
52.44	173.02	0.565
52.46	173.15	0.565
52.47	173.28	0.565
52.48	173.42	0.566
52.50	173.55	0.566
52.51	173.68	0.566
52.52	173.82	0.566
52.54	173.95	0.567
52.55	174.08	0.567
52.56	174.22	0.567
52.58	174.35	0.567
52.59	174.48	0.567
52.60	174.62	0.568
52.62	174.75	0.568
52.63	174.88	0.568
52.64	175.02	0.568
52.66	175.15	0.568
52.67	175.28	0.569
52.68	175.42	0.569
52.70	175.55	0.569
52.71	175.68	0.569
52.72	175.82	0.569
52.74	175.95	0.570
52.75	176.09	0.570
52.76	176.22	0.570
52.78	176.35	0.570
52.79	176.49	0.571
52.80	176.62	0.571
52.82	176.75	0.571
52.83	176.89	0.571
52.84	177.02	0.571
52.86	177.15	0.571
52.87	177.29	0.572
52.88	177.42	0.572
52.90	177.55	0.572
52.91	177.69	0.572
52.92	177.82	0.573
52.94	177.95	0.573
52.95	178.09	0.573
52.96	178.22	0.573
52.98	178.35	0.573
52.99	178.49	0.573
53.00	178.62	0.574
53.02	178.75	0.574
53.03	178.89	0.574
53.04	179.02	0.574
53.06	179.15	0.575
53.07	179.29	0.575
53.08	179.42	0.575
53.10	179.55	0.575
53.11	179.69	0.576
53.12	179.82	0.576
53.14	179.95	0.576
53.15	180.09	0.576
53.16	180.22	0.577
53.18	180.35	0.577
53.19	180.49	0.577
53.20	180.62	0.578
53.22	180.75	0.578
53.23	180.89	0.578
53.24	181.02	0.579
53.26	181.15	0.579
53.27	181.29	0.579
53.28	181.42	0.580
53.30	181.55	0.580
53.31	181.69	0.580
53.32	181.82	0.581
53.34	181.95	0.581
53.35	182.09	0.581
53.36	182.22	0.582
53.38	182.35	0.582
53.39	182.49	0.582
53.40	182.62	0.583
53.42	182.75	0.583
53.43	182.89	0.583
53.44	183.02	0.584
53.46	183.15	0.584
53.47	183.28	0.584
53.48	183.42	0.585
53.50	183.55	0.585
53.51	183.69	0.585
53.52	183.82	0.586
53.54	183.95	0.586
53.55	184.08	0.587
53.56	184.22	0.587
53.58	184.35	0.587
53.59	184.48	0.588
53.60	184.62	0.588
53.62	184.75	0.589
53.63	184.89	0.589
53.64	185.02	0.590
53.66	185.15	0.590
53.67	185.29	0.591
53.68	185.42	0.591
53.70	185.55	0.592
53.71	185.69	0.592
53.72	185.82	0.593
53.74	185.95	0.593
53.75	186.09	0.594
53.76	186.22	0.594
53.78	186.35	0.595
53.79	186.49	0.595
53.80	186.62	0.596
53.82	186.75	0.596
53.83	186.88	0.597
53.84	187.02	0.597
53.86	187.15	0.598
53.87	187.29	0.599
53.88	187.42	0.599
53.90	187.55	0.600
53.91	187.69	0.600
53.92	187.82	0.601
53.94	187.95	0.601
53.95	188.08	0.603
53.96	188.22	0.604
53.98	188.35	0.604
53.99	188.48	0.605
54.00	188.62	0.605
54.02	188.75	0.606
54.03	188.89	0.606
54.04	189.02	0.607
54.06	189.15	0.608
54.07	189.28	0.609
54.08	189.42	0.609
54.10	189.55	0.610
54.11	189.69	0.610
54.12	189.82	0.611
54.14	189.95	0.611
54.15	190.08	0.612
54.16	190.22	0.612
54.18	190.35	0.613
54.19	190.48	0.614
54.20	190.62	0.614
54.22	190.75	0.615
54.23	190.88	0.615
54.24	191.02	0.616
54.26	191.15	0.617
54.27	191.28	0.617
54.28	191.42	0.618
54.30	191.55	0.618
54.31	191.68	0.619
54.32	191.82	0.620
54.34	191.95	0.620
54.35	192.08	0.621
54.36	192.22	0.621
54.38	192.35	0.622
54.39	192.48	0.623
54.40	192.62	0.623
54.42	192.75	0.624
54.43	192.88	0.624
54.44	193.02	0.625
54.46	193.15	0.626
54.47	193.28	0.626
54.48	193.42	0.627
54.50	193.55	0.628
54.51	193.68	0.629
54.52	193.82	0.630
54.54	193.95	0.630
54.55	194.08	0.631
54.56	194.22	0.632
54.58	194.35	0.632
54.59	194.48	0.633
54.60	194.62	0.634
54.62	194.75	0.634
54.63	194.88	0.635
54.64	195.02	0.636
54.66	195.15	0.636
54.67	195.28	0.637
54.68	195.42	0.638
54.70	195.55	0.639
54.71	195.68	0.640
54.72	195.82	0.640
54.74	195.95	0.641
54.75	196.08	0.642
54.76	196.22	0.643
54.78	196.35	0.644
54.79	196.48	0.645
54.80	196.62	0.646
54.82	196.75	0.647
54.83	196.88	0.647
54.84	197.02	0.648
54.86	197.15	0.649
54.87	197.28	0.650
54.88	197.42	0.650
54.90	197.55	0.651
54.91	197.68	0.652
54.92	197.82	0.652
54.94	197.95	0.653
54.95	198.08	0.654
54.96	198.21	0.654
54.98	198.35	0.655
54.99	198.48	0.655
55.00	198.62	0.655
55.02	198.75	0.655
55.03	198.88	0.655
55.04	199.02	0.655
55.06	199.15	0.655
55.07	199.28	0.655
55.08	199.42	0.655
55.10	199.55	0.655
55.11	199.68	0.655
55.12	199.82	0.655
55.14	199.95	0.655
55.15	200.08	0.655
55.16	200.22	0.655
55.18	200.35	0.655
55.19	200.48	0.655
55.20	200.62	0.655
55.22	200.75	0.655
55.23	200.88	0.655
55.24	201.02	0.655
55.26	201.15	0.655
55.27	201.28	0.655
55.28	201.42	0.654
55.30	201.55	0.654
55.31	201.68	0.653
55.32	201.82	0.651
55.34	201.95	0.651
55.35	202.08	0.649
55.36	202.22	0.647
55.38	202.35	0.646
55.39	202.48	0.646
55.40	202.62	0.645
55.42	202.75	0.644
55.43	202.89	0.642
55.44	203.02	0.640
55.46	203.15	0.640
55.47	203.29	0.639
55.48	203.42	0.639
55.50	203.55	0.639
55.51	203.69	0.638
55.52	203.82	0.638
55.54	203.95	0.638
55.55	204.09	0.638
55.56	204.22	0.636
55.58	204.36	0.634
55.59	204.49	0.632
55.60	204.62	0.631
55.62	204.76	0.628
55.63	204.89	0.627
55.64	205.02	0.626
55.66	205.16	0.626
55.67	205.29	0.626
55.68	205.42	0.625
55.70	205.56	0.625
55.71	205.69	0.624
55.72	205.82	0.624
55.74	205.96	0.623
55.75	206.09	0.620
55.76	206.22	0.618
55.78	206.36	0.617
55.79	206.49	0.612
55.80	206.62	0.809
55.82	206.74	0.818
55.83	206.88	0.674
55.84	207.01	0.653
55.86	207.15	0.640
55.87	207.28	0.637
55.88	207.42	0.636
55.90	207.55	0.637
55.91	207.69	0.637
55.92	207.82	0.635
55.94	207.95	0.628
55.95	208.09
55.96	208.22
55.98	208.36
55.99	208.49
56.00